Workbook

Sheet HU3
A1: HU3 - Ballina - Top Equipment Losses, 16 Mar - 15 Sep 2026 (Ignition; shutdown, utilities, warnings, material and controller stops removed)
A3: Equipment target | B3: Hours | C3: Stops | D3: Avg min / stop | E3: % of equipment loss | F3: Cumulative % (to 100%) | G3: % of total time
A4: ST406 Valve Feed: Valve in pickup position A/B not present | B4: =SUMIFS('HU3 Stop Cycles'!$D:$D,'HU3 Stop Cycles'!$L:$L,$A4) | C4: =COUNTIFS('HU3 Stop Cycles'!$L:$L,$A4) | D4: =IF(C4=0,0,B4*60/C4) | E4: =B4/$B$30 | F4: =E4 | G4: =B4/4394.093873055555
A5: ST50 Hot Stamp: Hot printer A/B not ready for operation | B5: =SUMIFS('HU3 Stop Cycles'!$D:$D,'HU3 Stop Cycles'!$L:$L,$A5) | C5: =COUNTIFS('HU3 Stop Cycles'!$L:$L,$A5) | D5: =IF(C5=0,0,B5*60/C5) | E5: =B5/$B$30 | F5: =F4+E5 | G5: =B5/4394.093873055555
A6: ST211 Gasket Feed: Limit switch fault Fork A/B in working position | B6: =SUMIFS('HU3 Stop Cycles'!$D:$D,'HU3 Stop Cycles'!$L:$L,$A6) | C6: =COUNTIFS('HU3 Stop Cycles'!$L:$L,$A6) | D6: =IF(C6=0,0,B6*60/C6) | E6: =B6/$B$30 | F6: =F5+E6 | G6: =B6/4394.093873055555
A7: ST210 Gasket Feed: Limit switch fault Fork A/B in working position | B7: =SUMIFS('HU3 Stop Cycles'!$D:$D,'HU3 Stop Cycles'!$L:$L,$A7) | C7: =COUNTIFS('HU3 Stop Cycles'!$L:$L,$A7) | D7: =IF(C7=0,0,B7*60/C7) | E7: =B7/$B$30 | F7: =F6+E7 | G7: =B7/4394.093873055555
A8: ST70 Moon Punch: Punch waste A/B not exhausted | B8: =SUMIFS('HU3 Stop Cycles'!$D:$D,'HU3 Stop Cycles'!$L:$L,$A8) | C8: =COUNTIFS('HU3 Stop Cycles'!$L:$L,$A8) | D8: =IF(C8=0,0,B8*60/C8) | E8: =B8/$B$30 | F8: =F7+E8 | G8: =B8/4394.093873055555
A9: ST74 Valve Vision: Valve left/right inserted but not found - Check for valve on web | B9: =SUMIFS('HU3 Stop Cycles'!$D:$D,'HU3 Stop Cycles'!$L:$L,$A9) | C9: =COUNTIFS('HU3 Stop Cycles'!$L:$L,$A9) | D9: =IF(C9=0,0,B9*60/C9) | E9: =B9/$B$30 | F9: =F8+E9 | G9: =B9/4394.093873055555
A10: ST38 Anti-Slosh: Vacuum counter plate A/B not present | B10: =SUMIFS('HU3 Stop Cycles'!$D:$D,'HU3 Stop Cycles'!$L:$L,$A10) | C10: =COUNTIFS('HU3 Stop Cycles'!$L:$L,$A10) | D10: =IF(C10=0,0,B10*60/C10) | E10: =B10/$B$30 | F10: =F9+E10 | G10: =B10/4394.093873055555
A11: ST158 Reinforcement Tape: Vacuum splice module not present | B11: =SUMIFS('HU3 Stop Cycles'!$D:$D,'HU3 Stop Cycles'!$L:$L,$A11) | C11: =COUNTIFS('HU3 Stop Cycles'!$L:$L,$A11) | D11: =IF(C11=0,0,B11*60/C11) | E11: =B11/$B$30 | F11: =F10+E11 | G11: =B11/4394.093873055555
A12: ST76 Periphery Seal: Sealing head A/B has reached adjusted current limit | B12: =SUMIFS('HU3 Stop Cycles'!$D:$D,'HU3 Stop Cycles'!$L:$L,$A12) | C12: =COUNTIFS('HU3 Stop Cycles'!$L:$L,$A12) | D12: =IF(C12=0,0,B12*60/C12) | E12: =B12/$B$30 | F12: =F11+E12 | G12: =B12/4394.093873055555
A13: ST74 Valve Vision: Valve left/right out of area - Check for valve on web | B13: =SUMIFS('HU3 Stop Cycles'!$D:$D,'HU3 Stop Cycles'!$L:$L,$A13) | C13: =COUNTIFS('HU3 Stop Cycles'!$L:$L,$A13) | D13: =IF(C13=0,0,B13*60/C13) | E13: =B13/$B$30 | F13: =F12+E13 | G13: =B13/4394.093873055555
A14: ST226 Gasket Feed: General error | B14: =SUMIFS('HU3 Stop Cycles'!$D:$D,'HU3 Stop Cycles'!$L:$L,$A14) | C14: =COUNTIFS('HU3 Stop Cycles'!$L:$L,$A14) | D14: =IF(C14=0,0,B14*60/C14) | E14: =B14/$B$30 | F14: =F13+E14 | G14: =B14/4394.093873055555
A15: ST26 PAD Vision: TCP fault. See diagnostic page | B15: =SUMIFS('HU3 Stop Cycles'!$D:$D,'HU3 Stop Cycles'!$L:$L,$A15) | C15: =COUNTIFS('HU3 Stop Cycles'!$L:$L,$A15) | D15: =IF(C15=0,0,B15*60/C15) | E15: =B15/$B$30 | F15: =F14+E15 | G15: =B15/4394.093873055555
A16: ST86 Offload: Consecutive fault side A/B | B16: =SUMIFS('HU3 Stop Cycles'!$D:$D,'HU3 Stop Cycles'!$L:$L,$A16) | C16: =COUNTIFS('HU3 Stop Cycles'!$L:$L,$A16) | D16: =IF(C16=0,0,B16*60/C16) | E16: =B16/$B$30 | F16: =F15+E16 | G16: =B16/4394.093873055555
... A28: ST406 Valve Feed: Consecutive fault side A/B | B28: =SUMIFS('HU3 Stop Cycles'!$D:$D,'HU3 Stop Cycles'!$L:$L,$A28) | C28: =COUNTIFS('HU3 Stop Cycles'!$L:$L,$A28) | D28: =IF(C28=0,0,B28*60/C28) | E28: =B28/$B$30 | F28: =F27+E28 | G28: =B28/4394.093873055555
A29: Other (156 smaller equipment losses) | B29: =SUMIFS('HU3 Stop Cycles'!$D:$D,'HU3 Stop Cycles'!$J:$J,"Equipment fault")-SUM(B4:B28) | C29: =COUNTIFS('HU3 Stop Cycles'!$J:$J,"Equipment fault")-SUM(C4:C28) | D29: =IF(C29=0,0,B29*60/C29) | E29: =B29/$B$30 | F29: =F28+E29 | G29: =B29/4394.093873055555
A30: Total equipment faults | B30: =SUM(B4:B29) | C30: =SUM(C4:C29) | D30: =IF(C30=0,0,B30*60/C30) | E30: =B30/$B$30 | F30: =F29 | G30: =B30/4394.093873055555
A32: Each target merges A/B and left/right sides and sensor numbers within a station (e.g. ST406 pickup position A and B), so micro-stop problems show as one target. Excluded categories (shutdown, operator/line warnings, utilities, controller cycle-time, material supply) are on the HU3 Equipment Focus tab. Source: HU3 Stop Cycles tab.
A33: Orange rows = stations on your focus list (ST86, 74, 22, 70, 51, web guiding 147).

Sheet HU3 Pareto (all stops)
A1: HU3 - Ballina - Top Losses, 16 Mar - 15 Sep 2026 (Ignition, all stops)
A3: Loss | B3: Hours | C3: % of Total Time | D3: Cumulative % (to Perfect Performance) | E3: Of which inferred hrs
A4: OEE - Running / Baseline | B4: 1384.0189 | C4: =B4/B32 | D4: =C4
A5: Shutdown / no production (>24 h) | B5: =SUMIFS('HU3 Stop Cycles'!$D:$D,'HU3 Stop Cycles'!$F:$F,$A5) | C5: =B5/$B$32 | D5: =D4+C5 | E5: =SUMIFS('HU3 Stop Cycles'!$H:$H,'HU3 Stop Cycles'!$F:$F,$A5)
A6: A stop button has been pressed too long | B6: =SUMIFS('HU3 Stop Cycles'!$D:$D,'HU3 Stop Cycles'!$F:$F,$A6) | C6: =B6/$B$32 | D6: =D5+C6 | E6: =SUMIFS('HU3 Stop Cycles'!$H:$H,'HU3 Stop Cycles'!$F:$F,$A6)
A7: 1A07-1B1 Main air valve basic machine pressure not present | B7: =SUMIFS('HU3 Stop Cycles'!$D:$D,'HU3 Stop Cycles'!$F:$F,$A7) | C7: =B7/$B$32 | D7: =D6+C7 | E7: =SUMIFS('HU3 Stop Cycles'!$H:$H,'HU3 Stop Cycles'!$F:$F,$A7)
A8: MSM-Bulge A: At least one station takes longer than maximum allowed | B8: =SUMIFS('HU3 Stop Cycles'!$D:$D,'HU3 Stop Cycles'!$F:$F,$A8) | C8: =B8/$B$32 | D8: =D7+C8 | E8: =SUMIFS('HU3 Stop Cycles'!$H:$H,'HU3 Stop Cycles'!$F:$F,$A8)
A9: End of reel (all stations) | B9: =SUMIFS('HU3 Stop Cycles'!$D:$D,'HU3 Stop Cycles'!$F:$F,$A9) | C9: =B9/$B$32 | D9: =D8+C9 | E9: =SUMIFS('HU3 Stop Cycles'!$H:$H,'HU3 Stop Cycles'!$F:$F,$A9)
A10: The machine empty run is finished | B10: =SUMIFS('HU3 Stop Cycles'!$D:$D,'HU3 Stop Cycles'!$F:$F,$A10) | C10: =B10/$B$32 | D10: =D9+C10 | E10: =SUMIFS('HU3 Stop Cycles'!$H:$H,'HU3 Stop Cycles'!$F:$F,$A10)
A11: The start of the machine is locked by the HMI | B11: =SUMIFS('HU3 Stop Cycles'!$D:$D,'HU3 Stop Cycles'!$F:$F,$A11) | C11: =B11/$B$32 | D11: =D10+C11 | E11: =SUMIFS('HU3 Stop Cycles'!$H:$H,'HU3 Stop Cycles'!$F:$F,$A11)
A12: System error of an axis, see fault message list | B12: =SUMIFS('HU3 Stop Cycles'!$D:$D,'HU3 Stop Cycles'!$F:$F,$A12) | C12: =B12/$B$32 | D12: =D11+C12 | E12: =SUMIFS('HU3 Stop Cycles'!$H:$H,'HU3 Stop Cycles'!$F:$F,$A12)
A13: 1211-2B1 Limit switch fault Fork B in working position | B13: =SUMIFS('HU3 Stop Cycles'!$D:$D,'HU3 Stop Cycles'!$F:$F,$A13) | C13: =B13/$B$32 | D13: =D12+C13 | E13: =SUMIFS('HU3 Stop Cycles'!$H:$H,'HU3 Stop Cycles'!$F:$F,$A13)
A14: 1A02-5T2 Battery in external UPS must be checked | B14: =SUMIFS('HU3 Stop Cycles'!$D:$D,'HU3 Stop Cycles'!$F:$F,$A14) | C14: =B14/$B$32 | D14: =D13+C14 | E14: =SUMIFS('HU3 Stop Cycles'!$H:$H,'HU3 Stop Cycles'!$F:$F,$A14)
A15: 1050-2K1 Hot printer A not ready for operation | B15: =SUMIFS('HU3 Stop Cycles'!$D:$D,'HU3 Stop Cycles'!$F:$F,$A15) | C15: =B15/$B$32 | D15: =D14+C15 | E15: =SUMIFS('HU3 Stop Cycles'!$H:$H,'HU3 Stop Cycles'!$F:$F,$A15)
A16: 1406-6B2 Valve in pickup position B not present | B16: =SUMIFS('HU3 Stop Cycles'!$D:$D,'HU3 Stop Cycles'!$F:$F,$A16) | C16: =B16/$B$32 | D16: =D15+C16 | E16: =SUMIFS('HU3 Stop Cycles'!$H:$H,'HU3 Stop Cycles'!$F:$F,$A16)
... A30: 1022-11B2 Flow monitor site cooling flow rate not OK | B30: =SUMIFS('HU3 Stop Cycles'!$D:$D,'HU3 Stop Cycles'!$F:$F,$A30) | C30: =B30/$B$32 | D30: =D29+C30 | E30: =SUMIFS('HU3 Stop Cycles'!$H:$H,'HU3 Stop Cycles'!$F:$F,$A30)
A31: Other (240 smaller losses) | B31: =SUM('HU3 Stop Cycles'!$D:$D)-SUM(B5:B30) | C31: =B31/$B$32 | D31: =D30+C31 | E31: =SUM('HU3 Stop Cycles'!$H:$H)-SUM(E5:E30)
A32: Perfect Performance | B32: =SUM(B4:B31) | C32: =SUM(C4:C31) | D32: =D31 | E32: =SUM(E5:E31)
A34: Source: HU3 tab (machine status log, 16 Mar 2026 - 15 Sep 2026, 100,000 events), fed from the HU3 Stop Cycles tab. A stop cycle = all MachineStatus=0 rows between one run (1) and the next. Each cycle is assigned to the reason code with the most time in it; cycles with no code take their most common alarm text ("Alarm text: ..."); otherwise they stay untagged. "Of which inferred hrs" = untagged hours given a reason by this method. Cycles over 200 h (7 Aug and 27 Aug, no production) are the "Shutdown / no production (>24 h)" row. Whole-cycle assignment moves some hours between codes compared with row-level totals. Total time 4,394 h. Losses ranked 16-25 are broken out from Other; the remaining smaller losses are in Other and listed on the HU3 All Losses tab.

Sheet HU3 Equipment Focus
A1: HU3 - Ballina - Equipment losses by station, 16 Mar - 15 Sep 2026 (Ignition; shutdown, utilities, warnings, material and controller stops removed)
A3: Loss category | B3: Hours | C3: Stops | D3: % of total time | E3: % of stopped time excl. shutdown
A4: Equipment fault | B4: =SUMIFS('HU3 Stop Cycles'!$D:$D,'HU3 Stop Cycles'!$J:$J,$A4) | C4: =COUNTIFS('HU3 Stop Cycles'!$J:$J,$A4) | D4: =B4/4394.093873055555 | E4: =B4/(SUM($B$4:$B$10)-$B$10)
A5: Operator / line (warning-type) | B5: =SUMIFS('HU3 Stop Cycles'!$D:$D,'HU3 Stop Cycles'!$J:$J,$A5) | C5: =COUNTIFS('HU3 Stop Cycles'!$J:$J,$A5) | D5: =B5/4394.093873055555 | E5: =B5/(SUM($B$4:$B$10)-$B$10)
A6: Utilities / infrastructure | B6: =SUMIFS('HU3 Stop Cycles'!$D:$D,'HU3 Stop Cycles'!$J:$J,$A6) | C6: =COUNTIFS('HU3 Stop Cycles'!$J:$J,$A6) | D6: =B6/4394.093873055555 | E6: =B6/(SUM($B$4:$B$10)-$B$10)
A7: Controller / machine cycle-time | B7: =SUMIFS('HU3 Stop Cycles'!$D:$D,'HU3 Stop Cycles'!$J:$J,$A7) | C7: =COUNTIFS('HU3 Stop Cycles'!$J:$J,$A7) | D7: =B7/4394.093873055555 | E7: =B7/(SUM($B$4:$B$10)-$B$10)
A8: Material supply (reels / infeed) | B8: =SUMIFS('HU3 Stop Cycles'!$D:$D,'HU3 Stop Cycles'!$J:$J,$A8) | C8: =COUNTIFS('HU3 Stop Cycles'!$J:$J,$A8) | D8: =B8/4394.093873055555 | E8: =B8/(SUM($B$4:$B$10)-$B$10)
A9: Untagged | B9: =SUMIFS('HU3 Stop Cycles'!$D:$D,'HU3 Stop Cycles'!$J:$J,$A9) | C9: =COUNTIFS('HU3 Stop Cycles'!$J:$J,$A9) | D9: =B9/4394.093873055555 | E9: =B9/(SUM($B$4:$B$10)-$B$10)
A10: Shutdown / no production | B10: =SUMIFS('HU3 Stop Cycles'!$D:$D,'HU3 Stop Cycles'!$J:$J,$A10) | C10: =COUNTIFS('HU3 Stop Cycles'!$J:$J,$A10) | D10: =B10/4394.093873055555
A13: Station | B13: Area (MI name) | C13: Your focus list | D13: Hours | E13: Stops | F13: Avg min / stop | G13: % of equipment loss | H13: Cumulative % | I13: Top fault at station
A14: 406 | B14: Valve Feed | D14: =SUMIFS('HU3 Stop Cycles'!$D:$D,'HU3 Stop Cycles'!$J:$J,"Equipment fault",'HU3 Stop Cycles'!$K:$K,$A14) | E14: =COUNTIFS('HU3 Stop Cycles'!$J:$J,"Equipment fault",'HU3 Stop Cycles'!$K:$K,$A14) | F14: =IF(E14=0,0,D14*60/E14) | G14: =D14/$B$4 | H14: =G14 | I14: 1406-6B2 Valve in pickup position B not present
A15: 050 | B15: Hot Stamp | D15: =SUMIFS('HU3 Stop Cycles'!$D:$D,'HU3 Stop Cycles'!$J:$J,"Equipment fault",'HU3 Stop Cycles'!$K:$K,$A15) | E15: =COUNTIFS('HU3 Stop Cycles'!$J:$J,"Equipment fault",'HU3 Stop Cycles'!$K:$K,$A15) | F15: =IF(E15=0,0,D15*60/E15) | G15: =D15/$B$4 | H15: =H14+G15 | I15: 1050-2K1 Hot printer A not ready for operation
A16: 211 | B16: Gasket Feed | D16: =SUMIFS('HU3 Stop Cycles'!$D:$D,'HU3 Stop Cycles'!$J:$J,"Equipment fault",'HU3 Stop Cycles'!$K:$K,$A16) | E16: =COUNTIFS('HU3 Stop Cycles'!$J:$J,"Equipment fault",'HU3 Stop Cycles'!$K:$K,$A16) | F16: =IF(E16=0,0,D16*60/E16) | G16: =D16/$B$4 | H16: =H15+G16 | I16: 1211-2B1 Limit switch fault Fork B in working position
A17: 210 | B17: Gasket Feed | D17: =SUMIFS('HU3 Stop Cycles'!$D:$D,'HU3 Stop Cycles'!$J:$J,"Equipment fault",'HU3 Stop Cycles'!$K:$K,$A17) | E17: =COUNTIFS('HU3 Stop Cycles'!$J:$J,"Equipment fault",'HU3 Stop Cycles'!$K:$K,$A17) | F17: =IF(E17=0,0,D17*60/E17) | G17: =D17/$B$4 | H17: =H16+G17 | I17: 1210-2B1 Limit switch fault Fork A in working position
A18: 074 | B18: Valve Vision | C18: ST74 Valve vision | D18: =SUMIFS('HU3 Stop Cycles'!$D:$D,'HU3 Stop Cycles'!$J:$J,"Equipment fault",'HU3 Stop Cycles'!$K:$K,$A18) | E18: =COUNTIFS('HU3 Stop Cycles'!$J:$J,"Equipment fault",'HU3 Stop Cycles'!$K:$K,$A18) | F18: =IF(E18=0,0,D18*60/E18) | G18: =D18/$B$4 | H18: =H17+G18 | I18: 1074 Valve right inserted but not found - Check for valve on web
A19: 038 | B19: Anti-Slosh | D19: =SUMIFS('HU3 Stop Cycles'!$D:$D,'HU3 Stop Cycles'!$J:$J,"Equipment fault",'HU3 Stop Cycles'!$K:$K,$A19) | E19: =COUNTIFS('HU3 Stop Cycles'!$J:$J,"Equipment fault",'HU3 Stop Cycles'!$K:$K,$A19) | F19: =IF(E19=0,0,D19*60/E19) | G19: =D19/$B$4 | H19: =H18+G19 | I19: 1038-12GQ2 Vacuum counter plate B not present
A20: 076 | B20: Periphery Seal | D20: =SUMIFS('HU3 Stop Cycles'!$D:$D,'HU3 Stop Cycles'!$J:$J,"Equipment fault",'HU3 Stop Cycles'!$K:$K,$A20) | E20: =COUNTIFS('HU3 Stop Cycles'!$J:$J,"Equipment fault",'HU3 Stop Cycles'!$K:$K,$A20) | F20: =IF(E20=0,0,D20*60/E20) | G20: =D20/$B$4 | H20: =H19+G20 | I20: 1076-1M1 Sealing head A has reached adjusted current limit
A21: 070 | B21: Moon Punch | C21: ST70 Valve window punch | D21: =SUMIFS('HU3 Stop Cycles'!$D:$D,'HU3 Stop Cycles'!$J:$J,"Equipment fault",'HU3 Stop Cycles'!$K:$K,$A21) | E21: =COUNTIFS('HU3 Stop Cycles'!$J:$J,"Equipment fault",'HU3 Stop Cycles'!$K:$K,$A21) | F21: =IF(E21=0,0,D21*60/E21) | G21: =D21/$B$4 | H21: =H20+G21 | I21: 1070-3B2 Punch waste B not exhausted
A22: 158 | B22: Reinforcement Tape | D22: =SUMIFS('HU3 Stop Cycles'!$D:$D,'HU3 Stop Cycles'!$J:$J,"Equipment fault",'HU3 Stop Cycles'!$K:$K,$A22) | E22: =COUNTIFS('HU3 Stop Cycles'!$J:$J,"Equipment fault",'HU3 Stop Cycles'!$K:$K,$A22) | F22: =IF(E22=0,0,D22*60/E22) | G22: =D22/$B$4 | H22: =H21+G22 | I22: 1158-6GQ1 Vacuum splice module not present
A23: 022 | B23: PAD Sealing | C23: ST22 Pad sealing | D23: =SUMIFS('HU3 Stop Cycles'!$D:$D,'HU3 Stop Cycles'!$J:$J,"Equipment fault",'HU3 Stop Cycles'!$K:$K,$A23) | E23: =COUNTIFS('HU3 Stop Cycles'!$J:$J,"Equipment fault",'HU3 Stop Cycles'!$K:$K,$A23) | F23: =IF(E23=0,0,D23*60/E23) | G23: =D23/$B$4 | H23: =H22+G23 | I23: 1022-11B2 Flow monitor site cooling flow rate not OK
A24: 082 | B24: Periphery Punch | D24: =SUMIFS('HU3 Stop Cycles'!$D:$D,'HU3 Stop Cycles'!$J:$J,"Equipment fault",'HU3 Stop Cycles'!$K:$K,$A24) | E24: =COUNTIFS('HU3 Stop Cycles'!$J:$J,"Equipment fault",'HU3 Stop Cycles'!$K:$K,$A24) | F24: =IF(E24=0,0,D24*60/E24) | G24: =D24/$B$4 | H24: =H23+G24 | I24: 1082-3B1 Limit switch fault Push out piston lowered
A25: 226 | B25: Gasket Feed | D25: =SUMIFS('HU3 Stop Cycles'!$D:$D,'HU3 Stop Cycles'!$J:$J,"Equipment fault",'HU3 Stop Cycles'!$K:$K,$A25) | E25: =COUNTIFS('HU3 Stop Cycles'!$J:$J,"Equipment fault",'HU3 Stop Cycles'!$K:$K,$A25) | F25: =IF(E25=0,0,D25*60/E25) | G25: =D25/$B$4 | H25: =H24+G25 | I25: 1226-1K1 General error
A26: 086 | B26: Offload | C26: ST86 Pick & place | D26: =SUMIFS('HU3 Stop Cycles'!$D:$D,'HU3 Stop Cycles'!$J:$J,"Equipment fault",'HU3 Stop Cycles'!$K:$K,$A26) | E26: =COUNTIFS('HU3 Stop Cycles'!$J:$J,"Equipment fault",'HU3 Stop Cycles'!$K:$K,$A26) | F26: =IF(E26=0,0,D26*60/E26) | G26: =D26/$B$4 | H26: =H25+G26 | I26: 1086 Consecutive fault side B
A27: 026 | B27: PAD Vision | D27: =SUMIFS('HU3 Stop Cycles'!$D:$D,'HU3 Stop Cycles'!$J:$J,"Equipment fault",'HU3 Stop Cycles'!$K:$K,$A27) | E27: =COUNTIFS('HU3 Stop Cycles'!$J:$J,"Equipment fault",'HU3 Stop Cycles'!$K:$K,$A27) | F27: =IF(E27=0,0,D27*60/E27) | G27: =D27/$B$4 | H27: =H26+G27 | I27: 1026-1B1 TCP fault. See diagnostic page:
A28: 227 | B28: Gasket Feed | D28: =SUMIFS('HU3 Stop Cycles'!$D:$D,'HU3 Stop Cycles'!$J:$J,"Equipment fault",'HU3 Stop Cycles'!$K:$K,$A28) | E28: =COUNTIFS('HU3 Stop Cycles'!$J:$J,"Equipment fault",'HU3 Stop Cycles'!$K:$K,$A28) | F28: =IF(E28=0,0,D28*60/E28) | G28: =D28/$B$4 | H28: =H27+G28 | I28: 1227-1K1 General error
A29: 159 | B29: Reinforcement Tape | D29: =SUMIFS('HU3 Stop Cycles'!$D:$D,'HU3 Stop Cycles'!$J:$J,"Equipment fault",'HU3 Stop Cycles'!$K:$K,$A29) | E29: =COUNTIFS('HU3 Stop Cycles'!$J:$J,"Equipment fault",'HU3 Stop Cycles'!$K:$K,$A29) | F29: =IF(E29=0,0,D29*60/E29) | G29: =D29/$B$4 | H29: =H28+G29 | I29: 1159-6GQ1 Vacuum splice module not present
A30: 090 | B30: Offload | D30: =SUMIFS('HU3 Stop Cycles'!$D:$D,'HU3 Stop Cycles'!$J:$J,"Equipment fault",'HU3 Stop Cycles'!$K:$K,$A30) | E30: =COUNTIFS('HU3 Stop Cycles'!$J:$J,"Equipment fault",'HU3 Stop Cycles'!$K:$K,$A30) | F30: =IF(E30=0,0,D30*60/E30) | G30: =D30/$B$4 | H30: =H29+G30 | I30: 1090-2B1 Error Cylinder switch
A31: 078 | B31: Anti-Slosh | D31: =SUMIFS('HU3 Stop Cycles'!$D:$D,'HU3 Stop Cycles'!$J:$J,"Equipment fault",'HU3 Stop Cycles'!$K:$K,$A31) | E31: =COUNTIFS('HU3 Stop Cycles'!$J:$J,"Equipment fault",'HU3 Stop Cycles'!$K:$K,$A31) | F31: =IF(E31=0,0,D31*60/E31) | G31: =D31/$B$4 | H31: =H30+G31 | I31: 1078-2B3 Limit switch fault Sealing head B in working position
A32: 018 | B32: Smash Seal | D32: =SUMIFS('HU3 Stop Cycles'!$D:$D,'HU3 Stop Cycles'!$J:$J,"Equipment fault",'HU3 Stop Cycles'!$K:$K,$A32) | E32: =COUNTIFS('HU3 Stop Cycles'!$J:$J,"Equipment fault",'HU3 Stop Cycles'!$K:$K,$A32) | F32: =IF(E32=0,0,D32*60/E32) | G32: =D32/$B$4 | H32: =H31+G32 | I32: 1018-16B1/16B2 Foil not in transport chain
A33: 129 | D33: =SUMIFS('HU3 Stop Cycles'!$D:$D,'HU3 Stop Cycles'!$J:$J,"Equipment fault",'HU3 Stop Cycles'!$K:$K,$A33) | E33: =COUNTIFS('HU3 Stop Cycles'!$J:$J,"Equipment fault",'HU3 Stop Cycles'!$K:$K,$A33) | F33: =IF(E33=0,0,D33*60/E33) | G33: =D33/$B$4 | H33: =H32+G33 | I33: 1129-1B1 Last splice has not been detected
A34: 147 | B34: Film/Fabric Feed | C34: Web guiding (ST43? - no ST43 in log; web guiding is 147) | D34: =SUMIFS('HU3 Stop Cycles'!$D:$D,'HU3 Stop Cycles'!$J:$J,"Equipment fault",'HU3 Stop Cycles'!$K:$K,$A34) | E34: =COUNTIFS('HU3 Stop Cycles'!$J:$J,"Equipment fault",'HU3 Stop Cycles'!$K:$K,$A34) | F34: =IF(E34=0,0,D34*60/E34) | G34: =D34/$B$4 | I34: 1147 Consecutive error guider, actuator or sensor out of range
A35: 051 | B35: Hot Stamp | C35: ST51 Vision hot stamp | D35: =SUMIFS('HU3 Stop Cycles'!$D:$D,'HU3 Stop Cycles'!$J:$J,"Equipment fault",'HU3 Stop Cycles'!$K:$K,$A35) | E35: =COUNTIFS('HU3 Stop Cycles'!$J:$J,"Equipment fault",'HU3 Stop Cycles'!$K:$K,$A35) | F35: =IF(E35=0,0,D35*60/E35) | G35: =D35/$B$4 | I35: 1051-1B1 Consecutive fault camera bad part side A
A37: Stations in orange are on your focus list. ST43 does not appear in the log: web guiding is logged at station 147; check the numbering with the line team.
A38: Station = number in the alarm message (1074-... = ST74). Equipment fault = station-coded faults only. The other categories are listed above and kept out of this ranking.
A39: Cumulative % is of total equipment-fault hours, so a station list limited to the top 20 plus your focus stations does not reach 100%.
A40: Stops are stop cycles (one run to the next); avg min / stop shows micro-stop (<3 min) versus long-fix stations.

Sheet HU3 Stop Cycles
A1: Cycle | B1: Start | C1: Last event | D1: Hours | E1: Events | F1: Assigned loss | G1: Basis | H1: Inferred hrs | I1: Codes seen in cycle (top 4 by time) | J1: Category | K1: Station | L1: Equipment target (sides merged)
A2: 1 | B2: 46097.546 | C2: 46097.547 | D2: 0.025461111 | E2: 3 | F2: 1410 Temperature not reached Heating sealing head A bottom | G2: Tagged (+ untagged rows absorbed) | H2: 0.0020869444 | I2: 1410 Temperature not reached Heating sealing head A bottom | J2: Equipment fault | K2: 410 | L2: ST410 Valve Seal: Temperature not reached Heating sealing head A/B bottom
A3: 2 | B3: 46097.55 | C3: 46097.557 | D3: 0.16333972 | E3: 3 | F3: 1038-15B1 Flow monitor flow rate not OK | G3: Tagged (+ untagged rows absorbed) | H3: 0.00097305556 | I3: 1038-15B1 Flow monitor flow rate not OK | J3: Equipment fault | K3: 038 | L3: ST38 Anti-Slosh: Flow monitor flow rate not OK
A4: 3 | B4: 46097.558 | C4: 46097.558 | D4: 0.072623056 | E4: 1 | F4: 1084 Bad parts box is full, please empty! | G4: Inferred from alarm text | H4: 0.072623056 | J4: Operator / line (warning-type) | K4: 084
A5: 4 | B5: 46097.572 | C5: 46097.572 | D5: 0.0097380556 | E5: 3 | F5: 1410 Temperature not reached Heating sealing head A bottom | G5: Tagged (+ untagged rows absorbed) | H5: 0.00097416667 | I5: 1410 Temperature not reached Heating sealing head A bottom | J5: Equipment fault | K5: 410 | L5: ST410 Valve Seal: Temperature not reached Heating sealing head A/B bottom
A6: 5 | B6: 46097.575 | C6: 46097.575 | D6: 0.016138889 | E6: 4 | F6: 1406-6B2 Valve in pickup position B not present | G6: Tagged (+ untagged rows absorbed) | H6: 0.00069638889 | I6: 1406-6B2 Valve in pickup position B not present | J6: Equipment fault | K6: 406 | L6: ST406 Valve Feed: Valve in pickup position A/B not present
A7: 8 | B7: 46097.576 | C7: 46097.576 | D7: 0.0059841667 | E7: 3 | F7: 1406-6B1 Valve in pickup position A not present | G7: Tagged (+ untagged rows absorbed) | H7: 0.0018091667 | I7: 1406-6B1 Valve in pickup position A not present | J7: Equipment fault | K7: 406 | L7: ST406 Valve Feed: Valve in pickup position A/B not present
A8: 9 | B8: 46097.577 | C8: 46097.577 | D8: 0.010297222 | E8: 3 | F8: 1046-2B1 Web has wrapped around the vacuum belt | G8: Tagged (+ untagged rows absorbed) | H8: 0.0059833333 | I8: 1046-2B1 Web has wrapped around the vacuum belt | J8: Equipment fault | K8: 046 | L8: ST46: Web has wrapped around the vacuum belt
A9: 10 | B9: 46097.578 | C9: 46097.581 | D9: 0.052586944 | E9: 4 | F9: 1158-5B1 All rolls empty - Please refill! | G9: Tagged (+ untagged rows absorbed) | H9: 0.00055638889 | I9: 1158-5B1 All rolls empty - Please refill! | J9: Material supply (reels / infeed) | K9: 158
A10: 11 | B10: 46097.582 | C10: 46097.584 | D10: 0.052033333 | E10: 4 | F10: 1159-5B1 All rolls empty - Please refill! | G10: Tagged (+ untagged rows absorbed) | H10: 0.0013908333 | I10: 1159-5B1 All rolls empty - Please refill! | J10: Material supply (reels / infeed) | K10: 159
A11: 12 | B11: 46097.586 | C11: 46097.589 | D11: 0.087507222 | E11: 3 | F11: 1A07-1B1 Main air valve basic machine pressure not present | G11: Inferred from alarm text | H11: 0.087507222 | J11: Utilities / infrastructure
A12: 13 | B12: 46097.591 | C12: 46097.617 | D12: 0.63592972 | E12: 10 | F12: MSM-Main: At least one station takes longer than maximum allowed | G12: Tagged - dominant of 2 codes | H12: 0.0098788889 | I12: MSM-Main: At least one station takes longer than maximum allowed; The guard of the machine is not closed | J12: Controller / machine cycle-time
A13: 15 | B13: 46097.618 | C13: 46097.623 | D13: 0.11477889 | E13: 4 | F13: Imminent overload of a servo axis: | G13: Inferred from alarm text | H13: 0.11477889 | J13: Controller / machine cycle-time
A14: 16 | B14: 46097.623 | C14: 46097.623 | D14: 0.0087638889 | E14: 1 | F14: 1412 Bad parts box is full, please empty! | G14: Inferred from alarm text | H14: 0.0087638889 | J14: Operator / line (warning-type) | K14: 412
A15: 17 | B15: 46097.624 | C15: 46097.624 | D15: 0.0075138889 | E15: 1 | F15: 1412 Bad parts box is full, please empty! | G15: Inferred from alarm text | H15: 0.0075138889 | J15: Operator / line (warning-type) | K15: 412
A16: 18 | B16: 46097.625 | C16: 46097.626 | D16: 0.049110278 | E16: 3 | F16: 1A07-1B1 Main air valve basic machine pressure not present | G16: Inferred from alarm text | H16: 0.049110278 | J16: Utilities / infrastructure
A17: 19 | B17: 46097.627 | C17: 46097.628 | D17: 0.017254722 | E17: 4 | F17: 1412 Bad parts box is full, please empty! | G17: Inferred from alarm text | H17: 0.017254722 | J17: Operator / line (warning-type) | K17: 412
A18: 20 | B18: 46097.628 | C18: 46097.628 | D18: 0.010295278 | E18: 1 | F18: Imminent overload of a servo axis: | G18: Inferred from alarm text | H18: 0.010295278 | J18: Controller / machine cycle-time
A19: 23 | B19: 46097.635 | C19: 46097.635 | D19: 0.014330556 | E19: 4 | F19: 1400-3B1 Infeed valve maximum product level permanently not reached | G19: Tagged (+ untagged rows absorbed) | H19: 0.00069611111 | I19: 1400-3B1 Infeed valve maximum product level permanently not reached | J19: Equipment fault | K19: 400 | L19: ST400 Valve Feed: Infeed valve maximum product level permanently not reached
A20: 25 | B20: 46097.64 | C20: 46097.641 | D20: 0.008485 | E20: 3 | F20: 1400-3B1 Infeed valve maximum product level permanently not reached | G20: Tagged (+ untagged rows absorbed) | H20: 0.0026425 | I20: 1400-3B1 Infeed valve maximum product level permanently not reached | J20: Equipment fault | K20: 400 | L20: ST400 Valve Feed: Infeed valve maximum product level permanently not reached
A21: 26 | B21: 46097.652 | C21: 46097.652 | D21: 0.012938056 | E21: 3 | F21: 1406-6B1 Valve in pickup position A not present | G21: Tagged (+ untagged rows absorbed) | H21: 0.0011138889 | I21: 1406-6B1 Valve in pickup position A not present | J21: Equipment fault | K21: 406 | L21: ST406 Valve Feed: Valve in pickup position A/B not present
A22: 27 | B22: 46097.656 | C22: 46097.656 | D22: 0.0082083333 | E22: 3 | F22: 1406-6B1 Valve in pickup position A not present | G22: Tagged (+ untagged rows absorbed) | H22: 0.0023647222 | I22: 1406-6B1 Valve in pickup position A not present | J22: Equipment fault | K22: 406 | L22: ST406 Valve Feed: Valve in pickup position A/B not present
A23: 28 | B23: 46097.661 | C23: 46097.662 | D23: 0.031163889 | E23: 5 | F23: 1400-3B1 Infeed valve maximum product level permanently not reached | G23: Tagged (+ untagged rows absorbed) | H23: 0.0020861111 | I23: 1400-3B1 Infeed valve maximum product level permanently not reached | J23: Equipment fault | K23: 400 | L23: ST400 Valve Feed: Infeed valve maximum product level permanently not reached
A24: 29 | B24: 46097.663 | C24: 46097.663 | D24: 0.011685278 | E24: 3 | F24: 1406-6B1 Valve in pickup position A not present | G24: Tagged (+ untagged rows absorbed) | H24: 0.0012527778 | I24: 1406-6B1 Valve in pickup position A not present | J24: Equipment fault | K24: 406 | L24: ST406 Valve Feed: Valve in pickup position A/B not present
A25: 33 | B25: 46097.673 | C25: 46097.673 | D25: 0.018228611 | E25: 4 | F25: 1038-12GQ2 Vacuum counter plate B not present | G25: Tagged (+ untagged rows absorbed) | H25: 0.00083527778 | I25: 1038-12GQ2 Vacuum counter plate B not present | J25: Equipment fault | K25: 038 | L25: ST38 Anti-Slosh: Vacuum counter plate A/B not present
A26: 34 | B26: 46097.673 | C26: 46097.674 | D26: 0.019476944 | E26: 4 | F26: 1038-12GQ2 Vacuum counter plate B not present | G26: Tagged (+ untagged rows absorbed) | H26: 0.0012519444 | I26: 1038-12GQ2 Vacuum counter plate B not present | J26: Equipment fault | K26: 038 | L26: ST38 Anti-Slosh: Vacuum counter plate A/B not present
A27: 35 | B27: 46097.674 | C27: 46097.675 | D27: 0.021843611 | E27: 4 | F27: 1038-12GQ2 Vacuum counter plate B not present | G27: Tagged (+ untagged rows absorbed) | H27: 0.00083416667 | I27: 1038-12GQ2 Vacuum counter plate B not present | J27: Equipment fault | K27: 038 | L27: ST38 Anti-Slosh: Vacuum counter plate A/B not present
A28: 37 | B28: 46097.683 | C28: 46097.684 | D28: 0.020872222 | E28: 4 | F28: 1406-2B1 Limit switch fault Stopper A opened | G28: Tagged (+ untagged rows absorbed) | H28: 0.0013916667 | I28: 1406-2B1 Limit switch fault Stopper A opened | J28: Equipment fault | K28: 406 | L28: ST406 Valve Feed: Limit switch fault Stopper A/B opened
A29: 38 | B29: 46097.685 | C29: 46097.686 | D29: 0.0185 | E29: 4 | F29: 1038-12GQ2 Vacuum counter plate B not present | G29: Tagged (+ untagged rows absorbed) | H29: 0.0011127778 | I29: 1038-12GQ2 Vacuum counter plate B not present | J29: Equipment fault | K29: 038 | L29: ST38 Anti-Slosh: Vacuum counter plate A/B not present
A30: 39 | B30: 46097.687 | C30: 46097.688 | D30: 0.034361111 | E30: 4 | F30: 1038-12GQ2 Vacuum counter plate B not present | G30: Tagged (+ untagged rows absorbed) | H30: 0.0011127778 | I30: 1038-12GQ2 Vacuum counter plate B not present | J30: Equipment fault | K30: 038 | L30: ST38 Anti-Slosh: Vacuum counter plate A/B not present
... A46: 64 | B46: 46097.755 | C46: 46097.755 | D46: 0.010298056 | E46: 3 | F46: 1400-3B1 Infeed valve maximum product level permanently not reached | G46: Tagged (+ untagged rows absorbed) | H46: 0.0023666667 | I46: 1400-3B1 Infeed valve maximum product level permanently not reached | J46: Equipment fault | K46: 400 | L46: ST400 Valve Feed: Infeed valve maximum product level permanently not reached
A47: 67 | B47: 46097.762 | C47: 46097.766 | D47: 0.098495556 | E47: 4 | F47: End of reel (all stations) | G47: Tagged (+ untagged rows absorbed) | H47: 0.00083444444 | I47: End of reel (all stations) | J47: Material supply (reels / infeed)
A48: 68 | B48: 46097.77 | C48: 46097.77 | D48: 0.017110278 | E48: 1 | F48: 1412 Bad parts box is full, please empty! | G48: Inferred from alarm text | H48: 0.017110278 | J48: Operator / line (warning-type) | K48: 412
A49: 71 | B49: 46097.777 | C49: 46097.794 | D49: 0.39387861 | E49: 4 | F49: 1A07-1B1 Main air valve basic machine pressure not present | G49: Inferred from alarm text | H49: 0.39387861 | J49: Utilities / infrastructure
A50: 76 | B50: 46097.795 | C50: 46097.795 | D50: 0.0059833333 | E50: 3 | F50: 1406-6B1 Valve in pickup position A not present | G50: Tagged (+ untagged rows absorbed) | H50: 0.0018091667 | I50: 1406-6B1 Valve in pickup position A not present | J50: Equipment fault | K50: 406 | L50: ST406 Valve Feed: Valve in pickup position A/B not present
A51: 77 | B51: 46097.796 | C51: 46097.796 | D51: 0.0057047222 | E51: 3 | F51: 1046-2B1 Web has wrapped around the vacuum belt | G51: Tagged (+ untagged rows absorbed) | H51: 0.000975 | I51: 1046-2B1 Web has wrapped around the vacuum belt | J51: Equipment fault | K51: 046 | L51: ST46: Web has wrapped around the vacuum belt
A52: 80 | B52: 46097.796 | C52: 46097.797 | D52: 0.025461111 | E52: 4 | F52: 1406-6B1 Valve in pickup position A not present | G52: Tagged (+ untagged rows absorbed) | H52: 0.0025055556 | I52: 1406-6B1 Valve in pickup position A not present | J52: Equipment fault | K52: 406 | L52: ST406 Valve Feed: Valve in pickup position A/B not present
A53: 81 | B53: 46097.8 | C53: 46097.8 | D53: 0.0066786111 | E53: 3 | F53: 1159-6GQ1 Vacuum splice module not present | G53: Tagged (+ untagged rows absorbed) | H53: 0.0020880556 | I53: 1159-6GQ1 Vacuum splice module not present | J53: Equipment fault | K53: 159 | L53: ST159 Reinforcement Tape: Vacuum splice module not present
A54: 87 | B54: 46097.805 | C54: 46097.807 | D54: 0.049526944 | E54: 4 | F54: 1406-6B1 Valve in pickup position A not present | G54: Tagged (+ untagged rows absorbed) | H54: 0.00083444444 | I54: 1406-6B1 Valve in pickup position A not present | J54: Equipment fault | K54: 406 | L54: ST406 Valve Feed: Valve in pickup position A/B not present
A55: 89 | B55: 46097.812 | C55: 46097.813 | D55: 0.031298333 | E55: 4 | F55: 1406-2B1 Limit switch fault Stopper A opened | G55: Tagged (+ untagged rows absorbed) | H55: 0.00097416667 | I55: 1406-2B1 Limit switch fault Stopper A opened | J55: Equipment fault | K55: 406 | L55: ST406 Valve Feed: Limit switch fault Stopper A/B opened
...

Sheet MI_Cap Analysis Reason_Sub
A1: HU3 - Ballina - Top Losses (MI Cap Analysis, 1 Jan - 4 Oct 2026, different period)
A3: Loss | B3: % of Total Time | C3: Cumulative % (to Perfect Performance) | D3: Comment
A4: OEE - Running / Baseline | B4: 0.3944 | C4: =B4 | D4: Baseline
A5: Mech/Elec Breakdown | Electrical | 1A02-5T2: Check UPS | B5: 0.0984 | C5: =C4+B5
A6: Mech/Elec Breakdown | General Fault | Mechanical | B6: 0.0875 | C6: =C5+B6
A7: Performance Loss | B7: 0.0652 | C7: =C6+B7
A8: Planned Loss | No Demand | B8: 0.0622 | C8: =C7+B8
A9: Mech/Elec Breakdown | Electrical | 1A02-21T2: Check UP | B9: 0.0374 | C9: =C8+B9
A10: Major Downtime | B10: 0.0316 | C10: =C9+B10
A11: Mech/Elec Breakdown | Electrical | 1A02-11T2: Check UP | B11: 0.0305 | C11: =C10+B11
A12: Machine | Offload | 084-ConveyorReject | B12: 0.0298 | C12: =C11+B12
A13: Machine | Valve Feed | 412 rejects Full | B13: 0.0241 | C13: =C12+B13
A14: Mech/Elec Breakdown | General Fault | Controls | B14: 0.0207 | C14: =C13+B14
A15: Quality Loss | B15: 0.0196 | C15: =C14+B15
A16: Minor Downtime | B16: 0.0184 | C16: =C15+B16
... A20: Other (108 smaller losses) | B20: 0.0672 | C20: =C19+B20
A21: Perfect Performance | B21: =SUM(B4:B20) | C21: =C20
A23: Source: MI_Cap Analysis Reason_Sub, 2026 YTD (% hours). Top 15 losses shown; remainder grouped as Other. Zero-value reasons excluded.

Sheet HU3 All Losses
A1: Loss (assigned from stop cycles) | B1: Hours | C1: % of Total Time | D1: Of which inferred hrs
A2: Shutdown / no production (>24 h) | B2: 849.73949 | C2: 0.19338219 | D2: 0
A3: A stop button has been pressed too long | B3: 447.4913 | C3: 0.10183927 | D3: 0.79327583
A4: 1A07-1B1 Main air valve basic machine pressure not present | B4: 285.7849 | C4: 0.065038416 | D4: 57.073564
A5: MSM-Bulge A: At least one station takes longer than maximum allowed | B5: 204.48031 | C5: 0.046535262 | D5: 17.676804
A6: End of reel (all stations) | B6: 169.48008 | C6: 0.038569973 | D6: 0.070264444
A7: The machine empty run is finished | B7: 91.895683 | C7: 0.020913455 | D7: 0.0064030556
A8: The start of the machine is locked by the HMI | B8: 63.669647 | C8: 0.014489824 | D8: 4.8440975
A9: System error of an axis, see fault message list | B9: 63.579838 | C9: 0.014469385 | D9: 0.81580528
A10: 1211-2B1 Limit switch fault Fork B in working position | B10: 58.871796 | C10: 0.013397938 | D10: 0.069568889
A11: 1A02-5T2 Battery in external UPS must be checked | B11: 56.825656 | C11: 0.012932281 | D11: 20.557818
A12: 1050-2K1 Hot printer A not ready for operation | B12: 53.00943 | C12: 0.012063791 | D12: 0.0040352778
A13: 1406-6B2 Valve in pickup position B not present | B13: 48.433868 | C13: 0.011022493 | D13: 0.34934
... A267: 1038-1B2 Transfer sealing end position at the back reached | B267: 0.0038952778 | C267: 8.8648033e-07 | D267: 0
